Workbook
Name Slicer_Diabetes_Status: #N/A
Name Slicer_Weight_Status: #N/A

Sheet Customer Names
A1: Customer ID | B1: name | C1: Title | D1: First Name | E1: Last Name
A2: Id1 | B2: Hawks, Ms. Kelly | C2: Ms. | D2: Kelly | E2: Hawks
A3: Id2 | B3: Lehner, Mr. Matthew D | C3: Mr. | D3: Matthew D | E3: Lehner
A4: Id3 | B4: Lu, Mr. Phil | C4: Mr. | D4: Phil | E4: Lu
A5: Id4 | B5: Osborne, Ms. Kelsey | C5: Ms. | D5: Kelsey | E5: Osborne
A6: Id5 | B6: Kadala, Ms. Kristyn | C6: Ms. | D6: Kristyn | E6: Kadala
A7: Id6 | B7: Baker, Mr. Russell B. | C7: Mr. | D7: Russell B. | E7: Baker
A8: Id7 | B8: Macpherson, Mr. Scott | C8: Mr. | D8: Scott | E8: Macpherson
A9: Id8 | B9: Hallman, Mr. Stephen | C9: Mr. | D9: Stephen | E9: Hallman
A10: Id9 | B10: Moran, Mr. Patrick R. | C10: Mr. | D10: Patrick R. | E10: Moran
A11: Id10 | B11: Benner, Ms. Brooke N. | C11: Ms. | D11: Brooke N. | E11: Benner
A12: Id11 | B12: Fierro Vargas, Ms. Paola Andrea | C12: Ms. | D12: Paola Andrea | E12: Fierro Vargas
... A2336: Id2335 | B2336: German, Mr. Aaron K | C2336: Mr. | D2336: Aaron K | E2336: German

Sheet Medical Examinations
A1: Customer ID | B1: BMI | C1: Weight Status | D1: HBA1C | E1: Diabetes Status | F1: Heart Issues | G1: Any Transplants | H1: Cancer history | I1: NumberOfMajorSurgeries | J1: smoker
A2: Id1 | B2: 47.41 | C2: Obesity | D2: 7.47 | E2: Diabetes | F2: No | G2: No | H2: No | I2: 0 | J2: yes
A3: Id2 | B3: 30.36 | C3: Obesity | D3: 5.77 | E3: Prediabetes | F3: No | G3: No | H3: No | I3: 0 | J3: yes
A4: Id3 | B4: 34.485 | C4: Obesity | D4: 11.87 | E4: Diabetes | F4: Yes | G4: No | H4: No | I4: 2 | J4: Yes
A5: Id4 | B5: 38.095 | C5: Obesity | D5: 6.05 | E5: Prediabetes | F5: No | G5: No | H5: No | I5: 0 | J5: yes
A6: Id5 | B6: 35.53 | C6: Obesity | D6: 5.45 | E6: Normal | F6: No | G6: No | H6: No | I6: 0 | J6: yes
A7: Id6 | B7: 32.8 | C7: Obesity | D7: 6.59 | E7: Diabetes | F7: No | G7: No | H7: No | I7: 0 | J7: yes
A8: Id7 | B8: 36.4 | C8: Obesity | D8: 6.07 | E8: Prediabetes | F8: No | G8: No | H8: No | I8: 0 | J8: yes
A9: Id8 | B9: 36.96 | C9: Obesity | D9: 7.93 | E9: Diabetes | F9: No | G9: No | H9: No | I9: 3 | J9: yes
A10: Id9 | B10: 41.14 | C10: Obesity | D10: 9.58 | E10: Diabetes | F10: Yes | G10: No | H10: Yes | I10: 1 | J10: Yes
A11: Id10 | B11: 38.06 | C11: Obesity | D11: 10.79 | E11: Diabetes | F11: No | G11: No | H11: No | I11: 0 | J11: yes
A12: Id11 | B12: 37.7 | C12: Obesity | D12: 5.96 | E12: Prediabetes | F12: Yes | G12: No | H12: No | I12: 2 | J12: Yes
A13: Id12 | B13: 42.13 | C13: Obesity | D13: 11.9 | E13: Diabetes | F13: No | G13: No | H13: No | I13: 0 | J13: yes
... A2336: Id2335 | B2336: 17.58 | C2336: Underweight | D2336: 4.51 | E2336: Normal | F2336: No | G2336: No | H2336: No | I2336: 1 | J2336: No

Sheet Hospitalisation Details
A1: Customer ID | B1: year | C1: month | D1: date | E1: Date of Birth | F1: Age | G1: children | H1: charges | I1: Hospital tier | J1: City tier | K1: State ID
A2: Id2335 | B2: 1992 | C2: Jul | D2: 9 | E2: 33794 | F2: 30 | G2: 0 | H2: 563.84 | I2: tier - 2 | J2: tier - 3 | K2: R1013
A3: Id2334 | B3: 1992 | C3: Nov | D3: 30 | E3: 33938 | F3: 30 | G3: 0 | H3: 570.62 | I3: tier - 2 | J3: tier - 1 | K3: R1013
A4: Id2333 | B4: 1993 | C4: Jun | D4: 30 | E4: 34150 | F4: 29 | G4: 0 | H4: 600 | I4: tier - 2 | J4: tier - 1 | K4: R1013
A5: Id2332 | B5: 1992 | C5: Sep | D5: 13 | E5: 33860 | F5: 30 | G5: 0 | H5: 604.54 | I5: tier - 3 | J5: tier - 3 | K5: R1013
A6: Id2331 | B6: 1998 | C6: Jul | D6: 27 | E6: 36003 | F6: 24 | G6: 0 | H6: 637.26 | I6: tier - 3 | J6: tier - 3 | K6: R1013
A7: Id2330 | B7: 2001 | C7: Nov | D7: 20 | E7: 37215 | F7: 21 | G7: 0 | H7: 646.14 | I7: tier - 3 | J7: tier - 3 | K7: R1012
A8: Id2329 | B8: 1993 | C8: Jun | D8: 1 | E8: 34121 | F8: 30 | G8: 0 | H8: 650 | I8: tier - 3 | J8: tier - 3 | K8: R1013
A9: Id2328 | B9: 1995 | C9: Jul | D9: 4 | E9: 34884 | F9: 27 | G9: 0 | H9: 650 | I9: tier - 3 | J9: tier - 3 | K9: R1013
A10: Id2327 | B10: 2002 | C10: Nov | D10: 29 | E10: 37589 | F10: 20 | G10: 0 | H10: 668 | I10: tier - 3 | J10: tier - 2 | K10: R1012
A11: Id2326 | B11: 1997 | C11: Nov | D11: 9 | E11: 35743 | F11: 25 | G11: 0 | H11: 670 | I11: tier - 3 | J11: tier - 3 | K11: R1013
A12: Id2325 | B12: 2001 | C12: Sep | D12: 12 | E12: 37146 | F12: 21 | G12: 0 | H12: 687.54 | I12: tier - 3 | J12: tier - 2 | K12: R1013
A13: Id2324 | B13: 1999 | C13: Dec | D13: 26 | E13: 36520 | F13: 23 | G13: 0 | H13: 700 | I13: tier - 2 | J13: tier - 3 | K13: R1013
... A2344: Id1 | B2344: 1968 | C2344: Oct | D2344: 12 | E2344: 25123 | F2344: 54 | G2344: 0 | H2344: 63770.43 | I2344: tier - 1 | J2344: tier - 3 | K2344: R1013

Sheet Healthcare - New
A1: Customer ID | B1: First Name | C1: Last Name | D1: BMI | E1: Weight Status | F1: HBA1C | G1: Diabetes Status | H1: Heart Issues | I1: Any Transplants | J1: Cancer history | K1: NumberOfMajorSurgeries | L1: smoker | M1: Date of Birth | N1: Age | O1: charges | P1: Hospital tier | Q1: City tier | R1: State ID
A2: Id1 | B2: =VLOOKUP(A2,'Customer Names'!A2:D2336,4,0) -> Kelly | C2: =VLOOKUP(A2,'Customer Names'!A2:E2336,5,0) -> Hawks | D2: =VLOOKUP(A2,'Medical Examinations'!A2:B2336,2,0) -> 47.41 | E2: =VLOOKUP(A2,'Medical Examinations'!A2:C2336,3,0) -> Obesity | F2: =VLOOKUP(A2,'Medical Examinations'!A2:D2336,4,0) -> 7.47 | G2: =VLOOKUP(A2,'Medical Examinations'!A2:E2336,5,0) -> Diabetes | H2: =VLOOKUP(A2,'Medical Examinations'!A2:F2336,6,0) -> No | I2: =VLOOKUP(A2,'Medical Examinations'!A2:G2336,7,0) -> No | J2: =VLOOKUP(A2,'Medical Examinations'!A2:H2336,8,0) -> No | K2: =VLOOKUP(A2,'Medical Examinations'!A2:I2336,9,0) -> 0 | L2: =VLOOKUP(A2,'Medical Examinations'!A2:J2336,10,0) -> yes | M2: 25123 | N2: 54 | O2: 63770.43 | P2: tier - 1 | Q2: tier - 3 | R2: R1013
A3: Id2 | B3: =VLOOKUP(A3,'Customer Names'!A3:D2337,4,0) -> Matthew D | C3: =VLOOKUP(A3,'Customer Names'!A3:E2337,5,0) -> Lehner | D3: =VLOOKUP(A3,'Medical Examinations'!A3:B2337,2,0) -> 30.36 | E3: =VLOOKUP(A3,'Medical Examinations'!A3:C2337,3,0) -> Obesity | F3: =VLOOKUP(A3,'Medical Examinations'!A3:D2337,4,0) -> 5.77 | G3: =VLOOKUP(A3,'Medical Examinations'!A3:E2337,5,0) -> Prediabetes | H3: =VLOOKUP(A3,'Medical Examinations'!A3:F2337,6,0) -> No | I3: =VLOOKUP(A3,'Medical Examinations'!A3:G2337,7,0) -> No | J3: =VLOOKUP(A3,'Medical Examinations'!A3:H2337,8,0) -> No | K3: =VLOOKUP(A3,'Medical Examinations'!A3:I2337,9,0) -> 0 | L3: =VLOOKUP(A3,'Medical Examinations'!A3:J2337,10,0) -> yes | M3: 28284 | N3: 46 | O3: 62592.87 | P3: tier - 2 | Q3: tier - 3 | R3: R1013
A4: Id3 | B4: =VLOOKUP(A4,'Customer Names'!A4:D2338,4,0) -> Phil | C4: =VLOOKUP(A4,'Customer Names'!A4:E2338,5,0) -> Lu | D4: =VLOOKUP(A4,'Medical Examinations'!A4:B2338,2,0) -> 34.485 | E4: =VLOOKUP(A4,'Medical Examinations'!A4:C2338,3,0) -> Obesity | F4: =VLOOKUP(A4,'Medical Examinations'!A4:D2338,4,0) -> 11.87 | G4: =VLOOKUP(A4,'Medical Examinations'!A4:E2338,5,0) -> Diabetes | H4: =VLOOKUP(A4,'Medical Examinations'!A4:F2338,6,0) -> Yes | I4: =VLOOKUP(A4,'Medical Examinations'!A4:G2338,7,0) -> No | J4: =VLOOKUP(A4,'Medical Examinations'!A4:H2338,8,0) -> No | K4: =VLOOKUP(A4,'Medical Examinations'!A4:I2338,9,0) -> 2 | L4: =VLOOKUP(A4,'Medical Examinations'!A4:J2338,10,0) -> Yes | M4: 25822 | N4: 52 | O4: 60021.4 | P4: tier - 1 | Q4: tier - 1 | R4: R1012
A5: Id4 | B5: =VLOOKUP(A5,'Customer Names'!A5:D2339,4,0) -> Kelsey | C5: =VLOOKUP(A5,'Customer Names'!A5:E2339,5,0) -> Osborne | D5: =VLOOKUP(A5,'Medical Examinations'!A5:B2339,2,0) -> 38.095 | E5: =VLOOKUP(A5,'Medical Examinations'!A5:C2339,3,0) -> Obesity | F5: =VLOOKUP(A5,'Medical Examinations'!A5:D2339,4,0) -> 6.05 | G5: =VLOOKUP(A5,'Medical Examinations'!A5:E2339,5,0) -> Prediabetes | H5: =VLOOKUP(A5,'Medical Examinations'!A5:F2339,6,0) -> No | I5: =VLOOKUP(A5,'Medical Examinations'!A5:G2339,7,0) -> No | J5: =VLOOKUP(A5,'Medical Examinations'!A5:H2339,8,0) -> No | K5: =VLOOKUP(A5,'Medical Examinations'!A5:I2339,9,0) -> 0 | L5: =VLOOKUP(A5,'Medical Examinations'!A5:J2339,10,0) -> yes | M5: 33395 | N5: 32 | O5: 58571.07 | P5: tier - 1 | Q5: tier - 3 | R5: R1024
A6: Id5 | B6: =VLOOKUP(A6,'Customer Names'!A6:D2340,4,0) -> Kristyn | C6: =VLOOKUP(A6,'Customer Names'!A6:E2340,5,0) -> Kadala | D6: =VLOOKUP(A6,'Medical Examinations'!A6:B2340,2,0) -> 35.53 | E6: =VLOOKUP(A6,'Medical Examinations'!A6:C2340,3,0) -> Obesity | F6: =VLOOKUP(A6,'Medical Examinations'!A6:D2340,4,0) -> 5.45 | G6: =VLOOKUP(A6,'Medical Examinations'!A6:E2340,5,0) -> Normal | H6: =VLOOKUP(A6,'Medical Examinations'!A6:F2340,6,0) -> No | I6: =VLOOKUP(A6,'Medical Examinations'!A6:G2340,7,0) -> No | J6: =VLOOKUP(A6,'Medical Examinations'!A6:H2340,8,0) -> No | K6: =VLOOKUP(A6,'Medical Examinations'!A6:I2340,9,0) -> 0 | L6: =VLOOKUP(A6,'Medical Examinations'!A6:J2340,10,0) -> yes | M6: 32678 | N6: 33 | O6: 55135.4 | P6: tier - 1 | Q6: tier - 2 | R6: R1012
A7: Id6 | B7: =VLOOKUP(A7,'Customer Names'!A7:D2341,4,0) -> Russell B. | C7: =VLOOKUP(A7,'Customer Names'!A7:E2341,5,0) -> Baker | D7: =VLOOKUP(A7,'Medical Examinations'!A7:B2341,2,0) -> 32.8 | E7: =VLOOKUP(A7,'Medical Examinations'!A7:C2341,3,0) -> Obesity | F7: =VLOOKUP(A7,'Medical Examinations'!A7:D2341,4,0) -> 6.59 | G7: =VLOOKUP(A7,'Medical Examinations'!A7:E2341,5,0) -> Diabetes | H7: =VLOOKUP(A7,'Medical Examinations'!A7:F2341,6,0) -> No | I7: =VLOOKUP(A7,'Medical Examinations'!A7:G2341,7,0) -> No | J7: =VLOOKUP(A7,'Medical Examinations'!A7:H2341,8,0) -> No | K7: =VLOOKUP(A7,'Medical Examinations'!A7:I2341,9,0) -> 0 | L7: =VLOOKUP(A7,'Medical Examinations'!A7:J2341,10,0) -> yes | M7: 22862 | N7: 60 | O7: 52590.83 | P7: tier - 1 | Q7: tier - 3 | R7: R1011
A8: Id7 | B8: =VLOOKUP(A8,'Customer Names'!A8:D2342,4,0) -> Scott | C8: =VLOOKUP(A8,'Customer Names'!A8:E2342,5,0) -> Macpherson | D8: =VLOOKUP(A8,'Medical Examinations'!A8:B2342,2,0) -> 36.4 | E8: =VLOOKUP(A8,'Medical Examinations'!A8:C2342,3,0) -> Obesity | F8: =VLOOKUP(A8,'Medical Examinations'!A8:D2342,4,0) -> 6.07 | G8: =VLOOKUP(A8,'Medical Examinations'!A8:E2342,5,0) -> Prediabetes | H8: =VLOOKUP(A8,'Medical Examinations'!A8:F2342,6,0) -> No | I8: =VLOOKUP(A8,'Medical Examinations'!A8:G2342,7,0) -> No | J8: =VLOOKUP(A8,'Medical Examinations'!A8:H2342,8,0) -> No | K8: =VLOOKUP(A8,'Medical Examinations'!A8:I2342,9,0) -> 0 | L8: =VLOOKUP(A8,'Medical Examinations'!A8:J2342,10,0) -> yes | M8: 34634 | N8: 28 | O8: 51194.56 | P8: tier - 1 | Q8: tier - 3 | R8: R1011
A9: Id8 | B9: =VLOOKUP(A9,'Customer Names'!A9:D2343,4,0) -> Stephen | C9: =VLOOKUP(A9,'Customer Names'!A9:E2343,5,0) -> Hallman | D9: =VLOOKUP(A9,'Medical Examinations'!A9:B2343,2,0) -> 36.96 | E9: =VLOOKUP(A9,'Medical Examinations'!A9:C2343,3,0) -> Obesity | F9: =VLOOKUP(A9,'Medical Examinations'!A9:D2343,4,0) -> 7.93 | G9: =VLOOKUP(A9,'Medical Examinations'!A9:E2343,5,0) -> Diabetes | H9: =VLOOKUP(A9,'Medical Examinations'!A9:F2343,6,0) -> No | I9: =VLOOKUP(A9,'Medical Examinations'!A9:G2343,7,0) -> No | J9: =VLOOKUP(A9,'Medical Examinations'!A9:H2343,8,0) -> No | K9: =VLOOKUP(A9,'Medical Examinations'!A9:I2343,9,0) -> 3 | L9: =VLOOKUP(A9,'Medical Examinations'!A9:J2343,10,0) -> yes | M9: 21363 | N9: 64 | O9: 49577.66 | P9: tier - 2 | Q9: tier - 2 | R9: R1013
A10: Id9 | B10: =VLOOKUP(A10,'Customer Names'!A10:D2344,4,0) -> Patrick R. | C10: =VLOOKUP(A10,'Customer Names'!A10:E2344,5,0) -> Moran | D10: =VLOOKUP(A10,'Medical Examinations'!A10:B2344,2,0) -> 41.14 | E10: =VLOOKUP(A10,'Medical Examinations'!A10:C2344,3,0) -> Obesity | F10: =VLOOKUP(A10,'Medical Examinations'!A10:D2344,4,0) -> 9.58 | G10: =VLOOKUP(A10,'Medical Examinations'!A10:E2344,5,0) -> Diabetes | H10: =VLOOKUP(A10,'Medical Examinations'!A10:F2344,6,0) -> Yes | I10: =VLOOKUP(A10,'Medical Examinations'!A10:G2344,7,0) -> No | J10: =VLOOKUP(A10,'Medical Examinations'!A10:H2344,8,0) -> Yes | K10: =VLOOKUP(A10,'Medical Examinations'!A10:I2344,9,0) -> 1 | L10: =VLOOKUP(A10,'Medical Examinations'!A10:J2344,10,0) -> Yes | M10: 23258 | N10: 59 | O10: 48970.25 | P10: tier - 1 | Q10: tier - 2 | R10: R1013
A11: Id10 | B11: =VLOOKUP(A11,'Customer Names'!A11:D2345,4,0) -> Brooke N. | C11: =VLOOKUP(A11,'Customer Names'!A11:E2345,5,0) -> Benner | D11: =VLOOKUP(A11,'Medical Examinations'!A11:B2345,2,0) -> 38.06 | E11: =VLOOKUP(A11,'Medical Examinations'!A11:C2345,3,0) -> Obesity | F11: =VLOOKUP(A11,'Medical Examinations'!A11:D2345,4,0) -> 10.79 | G11: =VLOOKUP(A11,'Medical Examinations'!A11:E2345,5,0) -> Diabetes | H11: =VLOOKUP(A11,'Medical Examinations'!A11:F2345,6,0) -> No | I11: =VLOOKUP(A11,'Medical Examinations'!A11:G2345,7,0) -> No | J11: =VLOOKUP(A11,'Medical Examinations'!A11:H2345,8,0) -> No | K11: =VLOOKUP(A11,'Medical Examinations'!A11:I2345,9,0) -> 0 | L11: =VLOOKUP(A11,'Medical Examinations'!A11:J2345,10,0) -> yes | M11: 28853 | N11: 44 | O11: 48885.14 | P11: tier - 1 | Q11: tier - 2 | R11: R1013
A12: Id11 | B12: =VLOOKUP(A12,'Customer Names'!A12:D2346,4,0) -> Paola Andrea | C12: =VLOOKUP(A12,'Customer Names'!A12:E2346,5,0) -> Fierro Vargas | D12: =VLOOKUP(A12,'Medical Examinations'!A12:B2346,2,0) -> 37.7 | E12: =VLOOKUP(A12,'Medical Examinations'!A12:C2346,3,0) -> Obesity | F12: =VLOOKUP(A12,'Medical Examinations'!A12:D2346,4,0) -> 5.96 | G12: =VLOOKUP(A12,'Medical Examinations'!A12:E2346,5,0) -> Prediabetes | H12: =VLOOKUP(A12,'Medical Examinations'!A12:F2346,6,0) -> Yes | I12: =VLOOKUP(A12,'Medical Examinations'!A12:G2346,7,0) -> No | J12: =VLOOKUP(A12,'Medical Examinations'!A12:H2346,8,0) -> No | K12: =VLOOKUP(A12,'Medical Examinations'!A12:I2346,9,0) -> 2 | L12: =VLOOKUP(A12,'Medical Examinations'!A12:J2346,10,0) -> Yes | M12: 21753 | N12: 63 | O12: 48824.45 | P12: tier - 2 | Q12: tier - 1 | R12: R1011
A13: Id12 | B13: =VLOOKUP(A13,'Customer Names'!A13:D2347,4,0) -> David | C13: =VLOOKUP(A13,'Customer Names'!A13:E2347,5,0) -> Franz | D13: =VLOOKUP(A13,'Medical Examinations'!A13:B2347,2,0) -> 42.13 | E13: =VLOOKUP(A13,'Medical Examinations'!A13:C2347,3,0) -> Obesity | F13: =VLOOKUP(A13,'Medical Examinations'!A13:D2347,4,0) -> 11.9 | G13: =VLOOKUP(A13,'Medical Examinations'!A13:E2347,5,0) -> Diabetes | H13: =VLOOKUP(A13,'Medical Examinations'!A13:F2347,6,0) -> No | I13: =VLOOKUP(A13,'Medical Examinations'!A13:G2347,7,0) -> No | J13: =VLOOKUP(A13,'Medical Examinations'!A13:H2347,8,0) -> No | K13: =VLOOKUP(A13,'Medical Examinations'!A13:I2347,9,0) -> 0 | L13: =VLOOKUP(A13,'Medical Examinations'!A13:J2347,10,0) -> yes | M13: 24042 | N13: 57 | O13: 48675.52 | P13: tier - 1 | Q13: tier - 2 | R13: R1013
... A2336: Id2335 | B2336: =VLOOKUP(A2336,'Customer Names'!A2336:D4670,4,0) -> Aaron K | C2336: =VLOOKUP(A2336,'Customer Names'!A2336:E4670,5,0) -> German | D2336: =VLOOKUP(A2336,'Medical Examinations'!A2336:B4670,2,0) -> 17.58 | E2336: =VLOOKUP(A2336,'Medical Examinations'!A2336:C4670,3,0) -> Underweight | F2336: =VLOOKUP(A2336,'Medical Examinations'!A2336:D4670,4,0) -> 4.51 | G2336: =VLOOKUP(A2336,'Medical Examinations'!A2336:E4670,5,0) -> Normal | H2336: =VLOOKUP(A2336,'Medical Examinations'!A2336:F4670,6,0) -> No | I2336: =VLOOKUP(A2336,'Medical Examinations'!A2336:G4670,7,0) -> No | J2336: =VLOOKUP(A2336,'Medical Examinations'!A2336:H4670,8,0) -> No | K2336: =VLOOKUP(A2336,'Medical Examinations'!A2336:I4670,9,0) -> 1 | L2336: =VLOOKUP(A2336,'Medical Examinations'!A2336:J4670,10,0) -> No | M2336: 33794 | N2336: 30 | O2336: 563.84 | P2336: tier - 2 | Q2336: tier - 3 | R2336: R1013

Sheet Pivot Charts
A3: Count of Customer ID | B3: Cancer History | G3: Any Transplants | H3: Sum of NumberOfMajorSurgeries | I3: Average of HBA1C | M3: Age | N3: Average of BMI | O3: Average of HBA1C | S3: Age | T3: Average of charges
A4: Smoker | B4: No | C4: Yes | D4: Grand Total | G4: No | H4: 1417 | I4: 6.6704427 | M4: 18 | N4: 31.260372 | O4: 5.1409574 | S4: 18 | T4: 6610.9524
A5: No | B5: 1540 | C5: 307 | D5: 1847 | G5: yes | H5: 162 | I5: 5.1876389 | M5: 19 | N5: 29.654186 | O5: 5.1781395 | S5: 19 | T5: 9676.7031
A6: yes | B6: 404 | C6: 84 | D6: 488 | G6: Grand Total | H6: 1579 | I6: 6.5789979 | M6: 20 | N6: 28.018276 | O6: 9.3244828 | S6: 20 | T6: 7411.3848
A7: Grand Total | B7: 1944 | C7: 391 | D7: 2335 | M7: 21 | N7: 29.273721 | O7: 5.1174419 | S7: 21 | T7: 5213.3928
M8: 22 | N8: 32.581827 | O8: 5.2767308 | S8: 22 | T8: 9805.8033
M9: 23 | N9: 30.8293 | O9: 5.1892 | S9: 23 | T9: 11091.757
M10: 24 | N10: 29.0175 | O10: 5.1626087 | S10: 24 | T10: 9765.4772
M11: 25 | N11: 30.344211 | O11: 5.2589474 | S11: 25 | T11: 9183.5623
M12: 26 | N12: 30.441364 | O12: 5.1029545 | S12: 26 | T12: 5918.9727
M13: 27 | N13: 30.316275 | O13: 4.9407843 | S13: 27 | T13: 11845.238
M14: 28 | N14: 31.029286 | O14: 5.2207143 | S14: 28 | T14: 9217.9816
M15: 29 | N15: 30.763302 | O15: 5.2043396 | S15: 29 | T15: 9913.0674
M16: 30 | N16: 33.517768 | O16: 5.1835714 | S16: 30 | T16: 13786.891
M17: 31 | N17: 31.107065 | O17: 5.3330435 | S17: 31 | T17: 10345.285
M18: 32 | N18: 33.2464 | O18: 5.1798 | S18: 32 | T18: 14696.383
M19: 33 | N19: 31.452444 | O19: 5.0353333 | S19: 33 | T19: 11887.953
... M22: 36 | N22: 29.481667 | O22: 9.0571429 | S22: 36 | T22: 12288.675
A23: Average of charges | B23: Diabetes Status | M23: 37 | N23: 30.131538 | O23: 5.2648077 | S23: 37 | T23: 16500.829
A24: Wight Status | B24: Diabetes | C24: Normal | D24: Prediabetes | E24: Grand Total | M24: 38 | N24: 28.330568 | O24: 5.2577273 | S24: 38 | T24: 10218.887
A25: Normal Weight | B25: 12505.494 | C25: 7895.0242 | D25: 10388.144 | E25: 9839.7749 | G25: Average of charges | H25: Hospital tier | M25: 39 | N25: 30.269186 | O25: 5.2916279 | S25: 39 | T25: 14127.259
A26: Obesity | B26: 19102.58 | C26: 15138.797 | D26: 15500.496 | E26: 16610.798 | G26: State ID | H26: tier - 1 | I26: tier - 2 | J26: tier - 3 | K26: Grand Total | M26: 40 | N26: 31.033661 | O26: 5.3176786 | S26: 40 | T26: 12891.834
A27: Overweight | B27: 13884.317 | C27: 10374.281 | D27: 10006.633 | E27: 11407.547 | G27: R1011 | H27: 33080.952 | I27: 18995.717 | J27: 9249.5999 | K27: 19465.109 | M27: 41 | N27: 30.04375 | O27: 9.3903846 | S27: 41 | T27: 12027.665
A28: Underweight | B28: 7419.9433 | C28: 6909.651 | D28: 5624.4454 | E28: 6896.5461 | G28: R1012 | H28: 26110.94 | I28: 10331.423 | J28: 10178.677 | K28: 12014.352 | M28: 42 | N28: 30.411702 | O28: 5.2017021 | S28: 42 | T28: 13177.881
A29: Grand Total | B29: 15971.462 | C29: 12088.879 | D29: 12688.961 | E29: 13527.961 | G29: R1013 | H29: 31327.659 | I29: 8436.1582 | J29: 6888.4447 | K29: 10512.333 | M29: 43 | N29: 32.305 | O29: 5.2442 | S29: 43 | T29: 17978.458
G30: R1014 | H30: 13890.572 | I30: 2395.17 | J30: 16950.485 | K30: 13477.066 | M30: 44 | N30: 30.245 | O30: 9.2566667 | S30: 44 | T30: 15157.671
G31: R1015 | H31: 21523.52 | I31: 15675.543 | J31: 7567.6025 | K31: 13947.559 | M31: 45 | N31: 30.940465 | O31: 5.552093 | S31: 45 | T31: 15177.907
G32: R1016 | H32: 39868.616 | I32: 16075.963 | J32: 8129.453 | K32: 13586.819 | M32: 46 | N32: 30.956754 | O32: 5.3657895 | S32: 46 | T32: 17588.438
G33: R1017 | H33: 34070.596 | I33: 11362.91 | J33: 8666.7662 | K33: 14804.686 | M33: 47 | N33: 32.274902 | O33: 9.0052941 | S33: 47 | T33: 19262.247
G34: R1018 | H34: 33475.82 | I34: 10139.193 | J34: 12570.97 | K34: 13272.547 | M34: 48 | N34: 32.017241 | O34: 9.5634483 | S34: 48 | T34: 15250.069
G35: R1019 | H35: 27621.61 | I35: 8111.7109 | J35: 12706.976 | K35: 13631.024 | M35: 49 | N35: 29.947959 | O35: 9.5440816 | S35: 49 | T35: 14764.718
G36: R1020 | I36: 6759.9233 | J36: 11716.453 | K36: 9238.1883 | M36: 50 | N36: 30.550776 | O36: 5.2236207 | S36: 50 | T36: 16205.125
G37: R1021 | I37: 7663.8966 | J37: 11518.786 | K37: 8930.503 | M37: 51 | N37: 31.368304 | O37: 8.9482143 | S37: 51 | T37: 17318.501
G38: R1022 | I38: 10097.01 | J38: 11637.812 | K38: 10647.296 | M38: 52 | N38: 31.402155 | O38: 9.0668966 | S38: 52 | T38: 16569.89
G39: R1023 | H39: 18261.757 | I39: 13456.042 | J39: 12785.637 | K39: 13785.484 | M39: 53 | N39: 30.202736 | O39: 5.1579245 | S39: 53 | T39: 16028.355
G40: R1024 | H40: 32732.187 | I40: 10171.342 | J40: 13360.979 | K40: 12863.084 | M40: 54 | N40: 31.042245 | O40: 9.1555102 | S40: 54 | T40: 17860.058
G41: R1025 | I41: 6881.7642 | J41: 10510.314 | K41: 8786.7527 | M41: 55 | N41: 33.014889 | O41: 9.5128889 | S41: 55 | T41: 18446.838
G42: R1026 | H42: 18709.798 | I42: 11916.572 | J42: 12296.78 | K42: 12488.403 | M42: 56 | N42: 33.436771 | O42: 5.0845833 | S42: 56 | T42: 16999.76
G43: Unknown | H43: 20996.53 | K43: 20996.53 | M43: 57 | N43: 29.9157 | O43: 9.426 | S43: 57 | T43: 15701.894
G44: Grand Total | H44: 30128.79 | I44: 11862.615 | J44: 9460.9771 | K44: 13527.961 | M44: 58 | N44: 31.701279 | O44: 5.3502326 | S44: 58 | T44: 14947.535
...

Sheet Output file
A1: Data Cleaning
A2: Check for the number of missing values marked with '?' in each column of the “Medical Examinations” Table and "Hospitalization Details" Table. | B2: Medical examination table:2 values and Hospitalization Details:15 values (Highlighted in Yellow colour)
A3: Fill in the missing values of ‘month’ with Sep and ‘year’ with its average rounded to the nearest integer. | B3: Month updated in Col:C of Hospitalisation sheet and Year is 1982 (Highlighted in Yellow colour)
A4: Determine the most frequently occurring values in the ‘smoker’, 'Hospital tier' and 'City tier' columns, and fill in the missing values accordingly. | B4: Smoker:NO, Hospital tier :tier - 2, City tier:tier - 2 (Highlighted in Yellow colour)
A5: If any 'State ID' values are missing, consider filling them with 'Unknown' or using another appropriate strategy. | B5: Missing values renamed as :Unknown
A6: Data Transformation
A7: Split the ‘names’ column in the “Customer Names” Table into 3 meaningful columns: ‘Title’, ‘First Name’, and ‘Last Name’ | B7: Col:C, D and E in Customer Names sheet
A8: Convert the "NumberOfMajorSurgeries" column in the “Medical Examinations” Table to numerical data by replacing non-numeric characters with meaningful numerical values. | B8: No major surgery are replaced by numerical value as "0"
A9: Check for inconsistencies in the 'Heart Issues' and 'smoker' columns and propose corrective actions if necessary. | B9: yes are replaced by "Yes"
A10: Create a new column named “Weight Status” that categorizes BMI into different categories | B10: Added new col:C in Medical Examinations sheet (Highlighted with green)
A11: Create a new column named “Diabetes Status” and fill it as per the information given below: | B11: Added new col: E in Medical Examinations sheet (Highlighted with blue)
A12: Merge ‘year’, ‘month’ and ‘date’ columns in the “Hospitalization Details” Table into one column named ‘Date of Birth’ and format it in ‘DD-MMM-YYYY’ custom format. | B12: Added new col: E in Hospitalization Details sheet (Highlighted with Orange)
A13: Calculate the ‘Age’ of each customer based on their ‘Date of Birth’ and the date of collection of the dataset, which is 8th June 2023. | B13: Added new col: F in Hospitalization Details sheet (Highlighted with Red)
A14: Format ‘charges’ column as currency ($). | B14: col: H in Hospitalization Details sheet (Highlighted with Green)
A15: Data Exploration, Analysis & Visualization:
A16: Create a new sheet named “Healthcare", combine all three tables into one, using Customer ID as the common column, utilizing VLOOKUP. | B16: Added in the sheet "Healthcare"
A17: Retain the following necessary columns: Customer ID, First Name, BMI, HBA1C, Heart Issues, Any Transplants, Cancer history, NumberOfMajorSurgeries, smoker, Weight Status, Diabetes Status, Date of Birth, charges, Hospital tier, City tier, State ID, Age. | B17: Added in the sheet "Healthcare"
A18: Analysis using Pie/Donut Chart: | B18: Added in the sheet "Pivot Charts"
A19: Analysis using Column/Bar Chart: | B19: Added in the sheet "Pivot Charts"
A20: Analysis using Line/Scatter Plot: | B20: Added in the sheet "Dashboard"
A21: Dashboard Creation: | B21: Added in the sheet "Dashboard"

Sheet Dashboard
